Traceback (most recent call last):
  File "C:\Users\marclobr\Documents\Partner Demos\Misc Dev\SageMaker-finetune-automation\1. generate_synthetic_data.py", line 649, in main
    generator = EnhancedDataGenerator(args.config)
                ^^^^^^^^^^^^^^^^^^^^^^^^^^^^^^^^^^
  File "C:\Users\marclobr\Documents\Partner Demos\Misc Dev\SageMaker-finetune-automation\1. generate_synthetic_data.py", line 294, in __init__
    self.validate_config()
  File "C:\Users\marclobr\Documents\Partner Demos\Misc Dev\SageMaker-finetune-automation\1. generate_synthetic_data.py", line 312, in validate_config
    raise ValueError(f"Missing required configuration section: {section}")
ValueError: Missing required configuration section: domain_name

During handling of the above exception, another exception occurred:

Traceback (most recent call last):
  File "C:\Users\marclobr\Documents\Partner Demos\Misc Dev\SageMaker-finetune-automation\1. generate_synthetic_data.py", line 674, in <module>
    exit(main())
         ^^^^^^
  File "C:\Users\marclobr\Documents\Partner Demos\Misc Dev\SageMaker-finetune-automation\1. generate_synthetic_data.py", line 670, in main
    print(f"\u274c Error: {e}")
  File "C:\Program Files\WindowsApps\PythonSoftwareFoundation.Python.3.11_3.11.2544.0_x64__qbz5n2kfra8p0\Lib\encodings\cp1252.py", line 19, in encode
    return codecs.charmap_encode(input,self.errors,encoding_table)[0]
           ^^^^^^^^^^^^^^^^^^^^^^^^^^^^^^^^^^^^^^^^^^^^^^^^^^^^^^^
UnicodeEncodeError: 'charmap' codec can't encode character '\u274c' in position 0: character maps to <undefined>
